Internal Server Error: /edit-username/
Traceback (most recent call last):
  File "C:\Users\parit\AppData\Roaming\Python\Python313\site-packages\django\db\backends\utils.py", line 105, in _execute
    return self.cursor.execute(sql, params)
           ~~~~~~~~~~~~~~~~~~~^^^^^^^^^^^^^
  File "C:\Users\parit\AppData\Roaming\Python\Python313\site-packages\django\db\backends\mysql\base.py", line 76, in execute
    return self.cursor.execute(query, args)
           ~~~~~~~~~~~~~~~~~~~^^^^^^^^^^^^^
  File "C:\Users\parit\AppData\Roaming\Python\Python313\site-packages\MySQLdb\cursors.py", line 179, in execute
    res = self._query(mogrified_query)
  File "C:\Users\parit\AppData\Roaming\Python\Python313\site-packages\MySQLdb\cursors.py", line 330, in _query
    db.query(q)
    ~~~~~~~~^^^
  File "C:\Users\parit\AppData\Roaming\Python\Python313\site-packages\MySQLdb\connections.py", line 265, in query
    _mysql.connection.query(self, query)
    ~~~~~~~~~~~~~~~~~~~~~~~^^^^^^^^^^^^^
MySQLdb.IntegrityError: (1048, "Column 'username' cannot be null")

The above exception was the direct cause of the following exception:

Traceback (most recent call last):
  File "C:\Users\parit\AppData\Roaming\Python\Python313\site-packages\django\core\handlers\exception.py", line 55, in inner
    response = get_response(request)
  File "C:\Users\parit\AppData\Roaming\Python\Python313\site-packages\django\core\handlers\base.py", line 197, in _get_response
    response = wrapped_callback(request, *callback_args, **callback_kwargs)
  File "C:\Users\parit\AppData\Roaming\Python\Python313\site-packages\django\contrib\auth\decorators.py", line 60, in _view_wrapper
    return view_func(request, *args, **kwargs)
  File "C:\Users\parit\Downloads\Infosys_Project_Intelligent_Financial_Tracker (3) (1)\project_team4\Infosys_Project_Intelligent_Financial_Tracker\personal_financial_tracker\accounts\views.py", line 418, in edit_username
    request.user.save()
    ~~~~~~~~~~~~~~~~~^^
  File "C:\Users\parit\AppData\Roaming\Python\Python313\site-packages\django\contrib\auth\base_user.py", line 62, in save
    super().save(*args, **kwargs)
    ~~~~~~~~~~~~^^^^^^^^^^^^^^^^^
  File "C:\Users\parit\AppData\Roaming\Python\Python313\site-packages\django\db\models\base.py", line 891, in save
    self.save_base(
    ~~~~~~~~~~~~~~^
        using=using,
        ^^^^^^^^^^^^
    ...<2 lines>...
        update_fields=update_fields,
        ^^^^^^^^^^^^^^^^^^^^^^^^^^^^
    )
    ^
  File "C:\Users\parit\AppData\Roaming\Python\Python313\site-packages\django\db\models\base.py", line 997, in save_base
    updated = self._save_table(
        raw,
    ...<4 lines>...
        update_fields,
    )
  File "C:\Users\parit\AppData\Roaming\Python\Python313\site-packages\django\db\models\base.py", line 1129, in _save_table
    updated = self._do_update(
        base_qs, using, pk_val, values, update_fields, forced_update
    )
  File "C:\Users\parit\AppData\Roaming\Python\Python313\site-packages\django\db\models\base.py", line 1194, in _do_update
    return filtered._update(values) > 0
           ~~~~~~~~~~~~~~~~^^^^^^^^
  File "C:\Users\parit\AppData\Roaming\Python\Python313\site-packages\django\db\models\query.py", line 1278, in _update
    return query.get_compiler(self.db).execute_sql(CURSOR)
           ~~~~~~~~~~~~~~~~~~~~~~~~~~~~~~~~~~~~~~~^^^^^^^^
  File "C:\Users\parit\AppData\Roaming\Python\Python313\site-packages\django\db\models\sql\compiler.py", line 2003, in execute_sql
    cursor = super().execute_sql(result_type)
  File "C:\Users\parit\AppData\Roaming\Python\Python313\site-packages\django\db\models\sql\compiler.py", line 1574, in execute_sql
    cursor.execute(sql, params)
    ~~~~~~~~~~~~~~^^^^^^^^^^^^^
  File "C:\Users\parit\AppData\Roaming\Python\Python313\site-packages\django\db\backends\utils.py", line 122, in execute
    return super().execute(sql, params)
           ~~~~~~~~~~~~~~~^^^^^^^^^^^^^
  File "C:\Users\parit\AppData\Roaming\Python\Python313\site-packages\django\db\backends\utils.py", line 79, in execute
    return self._execute_with_wrappers(
           ~~~~~~~~~~~~~~~~~~~~~~~~~~~^
        sql, params, many=False, executor=self._execute
        ^^^^^^^^^^^^^^^^^^^^^^^^^^^^^^^^^^^^^^^^^^^^^^^
    )
    ^
  File "C:\Users\parit\AppData\Roaming\Python\Python313\site-packages\django\db\backends\utils.py", line 92, in _execute_with_wrappers
    return executor(sql, params, many, context)
  File "C:\Users\parit\AppData\Roaming\Python\Python313\site-packages\django\db\backends\utils.py", line 100, in _execute
    with self.db.wrap_database_errors:
         ^^^^^^^^^^^^^^^^^^^^^^^^^^^^
  File "C:\Users\parit\AppData\Roaming\Python\Python313\site-packages\django\db\utils.py", line 91, in __exit__
    raise dj_exc_value.with_traceback(traceback) from exc_value
  File "C:\Users\parit\AppData\Roaming\Python\Python313\site-packages\django\db\backends\utils.py", line 105, in _execute
    return self.cursor.execute(sql, params)
           ~~~~~~~~~~~~~~~~~~~^^^^^^^^^^^^^
  File "C:\Users\parit\AppData\Roaming\Python\Python313\site-packages\django\db\backends\mysql\base.py", line 76, in execute
    return self.cursor.execute(query, args)
           ~~~~~~~~~~~~~~~~~~~^^^^^^^^^^^^^
  File "C:\Users\parit\AppData\Roaming\Python\Python313\site-packages\MySQLdb\cursors.py", line 179, in execute
    res = self._query(mogrified_query)
  File "C:\Users\parit\AppData\Roaming\Python\Python313\site-packages\MySQLdb\cursors.py", line 330, in _query
    db.query(q)
    ~~~~~~~~^^^
  File "C:\Users\parit\AppData\Roaming\Python\Python313\site-packages\MySQLdb\connections.py", line 265, in query
    _mysql.connection.query(self, query)
    ~~~~~~~~~~~~~~~~~~~~~~~^^^^^^^^^^^^^
django.db.utils.IntegrityError: (1048, "Column 'username' cannot be null")
"POST /edit-username/ HTTP/1.1" 500 189214
Internal Server Error: /edit-username/
Traceback (most recent call last):
  File "C:\Users\parit\AppData\Roaming\Python\Python313\site-packages\django\db\backends\utils.py", line 105, in _execute
    return self.cursor.execute(sql, params)
           ~~~~~~~~~~~~~~~~~~~^^^^^^^^^^^^^
  File "C:\Users\parit\AppData\Roaming\Python\Python313\site-packages\django\db\backends\mysql\base.py", line 76, in execute
    return self.cursor.execute(query, args)
           ~~~~~~~~~~~~~~~~~~~^^^^^^^^^^^^^
  File "C:\Users\parit\AppData\Roaming\Python\Python313\site-packages\MySQLdb\cursors.py", line 179, in execute
    res = self._query(mogrified_query)
  File "C:\Users\parit\AppData\Roaming\Python\Python313\site-packages\MySQLdb\cursors.py", line 330, in _query
    db.query(q)
    ~~~~~~~~^^^
  File "C:\Users\parit\AppData\Roaming\Python\Python313\site-packages\MySQLdb\connections.py", line 265, in query
    _mysql.connection.query(self, query)
    ~~~~~~~~~~~~~~~~~~~~~~~^^^^^^^^^^^^^
MySQLdb.IntegrityError: (1048, "Column 'username' cannot be null")

The above exception was the direct cause of the following exception:

Traceback (most recent call last):
  File "C:\Users\parit\AppData\Roaming\Python\Python313\site-packages\django\core\handlers\exception.py", line 55, in inner
    response = get_response(request)
  File "C:\Users\parit\AppData\Roaming\Python\Python313\site-packages\django\core\handlers\base.py", line 197, in _get_response
    response = wrapped_callback(request, *callback_args, **callback_kwargs)
  File "C:\Users\parit\AppData\Roaming\Python\Python313\site-packages\django\contrib\auth\decorators.py", line 60, in _view_wrapper
    return view_func(request, *args, **kwargs)
  File "C:\Users\parit\Downloads\Infosys_Project_Intelligent_Financial_Tracker (3) (1)\project_team4\Infosys_Project_Intelligent_Financial_Tracker\personal_financial_tracker\accounts\views.py", line 418, in edit_username
    request.user.save()
    ~~~~~~~~~~~~~~~~~^^
  File "C:\Users\parit\AppData\Roaming\Python\Python313\site-packages\django\contrib\auth\base_user.py", line 62, in save
    super().save(*args, **kwargs)
    ~~~~~~~~~~~~^^^^^^^^^^^^^^^^^
  File "C:\Users\parit\AppData\Roaming\Python\Python313\site-packages\django\db\models\base.py", line 891, in save
    self.save_base(
    ~~~~~~~~~~~~~~^
        using=using,
        ^^^^^^^^^^^^
    ...<2 lines>...
        update_fields=update_fields,
        ^^^^^^^^^^^^^^^^^^^^^^^^^^^^
    )
    ^
  File "C:\Users\parit\AppData\Roaming\Python\Python313\site-packages\django\db\models\base.py", line 997, in save_base
    updated = self._save_table(
        raw,
    ...<4 lines>...
        update_fields,
    )
  File "C:\Users\parit\AppData\Roaming\Python\Python313\site-packages\django\db\models\base.py", line 1129, in _save_table
    updated = self._do_update(
        base_qs, using, pk_val, values, update_fields, forced_update
    )
  File "C:\Users\parit\AppData\Roaming\Python\Python313\site-packages\django\db\models\base.py", line 1194, in _do_update
    return filtered._update(values) > 0
           ~~~~~~~~~~~~~~~~^^^^^^^^
  File "C:\Users\parit\AppData\Roaming\Python\Python313\site-packages\django\db\models\query.py", line 1278, in _update
    return query.get_compiler(self.db).execute_sql(CURSOR)
           ~~~~~~~~~~~~~~~~~~~~~~~~~~~~~~~~~~~~~~~^^^^^^^^
  File "C:\Users\parit\AppData\Roaming\Python\Python313\site-packages\django\db\models\sql\compiler.py", line 2003, in execute_sql
    cursor = super().execute_sql(result_type)
  File "C:\Users\parit\AppData\Roaming\Python\Python313\site-packages\django\db\models\sql\compiler.py", line 1574, in execute_sql
    cursor.execute(sql, params)
    ~~~~~~~~~~~~~~^^^^^^^^^^^^^
  File "C:\Users\parit\AppData\Roaming\Python\Python313\site-packages\django\db\backends\utils.py", line 122, in execute
    return super().execute(sql, params)
           ~~~~~~~~~~~~~~~^^^^^^^^^^^^^
  File "C:\Users\parit\AppData\Roaming\Python\Python313\site-packages\django\db\backends\utils.py", line 79, in execute
    return self._execute_with_wrappers(
           ~~~~~~~~~~~~~~~~~~~~~~~~~~~^
        sql, params, many=False, executor=self._execute
        ^^^^^^^^^^^^^^^^^^^^^^^^^^^^^^^^^^^^^^^^^^^^^^^
    )
    ^
  File "C:\Users\parit\AppData\Roaming\Python\Python313\site-packages\django\db\backends\utils.py", line 92, in _execute_with_wrappers
    return executor(sql, params, many, context)
  File "C:\Users\parit\AppData\Roaming\Python\Python313\site-packages\django\db\backends\utils.py", line 100, in _execute
    with self.db.wrap_database_errors:
         ^^^^^^^^^^^^^^^^^^^^^^^^^^^^
  File "C:\Users\parit\AppData\Roaming\Python\Python313\site-packages\django\db\utils.py", line 91, in __exit__
    raise dj_exc_value.with_traceback(traceback) from exc_value
  File "C:\Users\parit\AppData\Roaming\Python\Python313\site-packages\django\db\backends\utils.py", line 105, in _execute
    return self.cursor.execute(sql, params)
           ~~~~~~~~~~~~~~~~~~~^^^^^^^^^^^^^
  File "C:\Users\parit\AppData\Roaming\Python\Python313\site-packages\django\db\backends\mysql\base.py", line 76, in execute
    return self.cursor.execute(query, args)
           ~~~~~~~~~~~~~~~~~~~^^^^^^^^^^^^^
  File "C:\Users\parit\AppData\Roaming\Python\Python313\site-packages\MySQLdb\cursors.py", line 179, in execute
    res = self._query(mogrified_query)
  File "C:\Users\parit\AppData\Roaming\Python\Python313\site-packages\MySQLdb\cursors.py", line 330, in _query
    db.query(q)
    ~~~~~~~~^^^
  File "C:\Users\parit\AppData\Roaming\Python\Python313\site-packages\MySQLdb\connections.py", line 265, in query
    _mysql.connection.query(self, query)
    ~~~~~~~~~~~~~~~~~~~~~~~^^^^^^^^^^^^^
django.db.utils.IntegrityError: (1048, "Column 'username' cannot be null")
"POST /edit-username/ HTTP/1.1" 500 189480
Internal Server Error: /edit-username/
Traceback (most recent call last):
  File "C:\Users\parit\AppData\Roaming\Python\Python313\site-packages\django\core\handlers\exception.py", line 55, in inner
    response = get_response(request)
  File "C:\Users\parit\AppData\Roaming\Python\Python313\site-packages\django\core\handlers\base.py", line 197, in _get_response
    response = wrapped_callback(request, *callback_args, **callback_kwargs)
  File "C:\Users\parit\AppData\Roaming\Python\Python313\site-packages\django\contrib\auth\decorators.py", line 60, in _view_wrapper
    return view_func(request, *args, **kwargs)
  File "C:\Users\parit\Downloads\Infosys_Project_Intelligent_Financial_Tracker (3) (1)\project_team4\Infosys_Project_Intelligent_Financial_Tracker\personal_financial_tracker\accounts\views.py", line 423, in edit_username
    return render(request, "edit_username.html")
  File "C:\Users\parit\AppData\Roaming\Python\Python313\site-packages\django\shortcuts.py", line 25, in render
    content = loader.render_to_string(template_name, context, request, using=using)
  File "C:\Users\parit\AppData\Roaming\Python\Python313\site-packages\django\template\loader.py", line 61, in render_to_string
    template = get_template(template_name, using=using)
  File "C:\Users\parit\AppData\Roaming\Python\Python313\site-packages\django\template\loader.py", line 19, in get_template
    raise TemplateDoesNotExist(template_name, chain=chain)
django.template.exceptions.TemplateDoesNotExist: edit_username.html
"GET /edit-username/ HTTP/1.1" 500 86199
Internal Server Error: /profile/
Traceback (most recent call last):
  File "C:\Users\parit\AppData\Roaming\Python\Python313\site-packages\django\core\handlers\exception.py", line 55, in inner
    response = get_response(request)
  File "C:\Users\parit\AppData\Roaming\Python\Python313\site-packages\django\core\handlers\base.py", line 197, in _get_response
    response = wrapped_callback(request, *callback_args, **callback_kwargs)
  File "C:\Users\parit\AppData\Roaming\Python\Python313\site-packages\django\contrib\auth\decorators.py", line 60, in _view_wrapper
    return view_func(request, *args, **kwargs)
  File "C:\Users\parit\Downloads\Infosys_Project_Intelligent_Financial_Tracker (3) (1)\project_team4\Infosys_Project_Intelligent_Financial_Tracker\personal_financial_tracker\accounts\views.py", line 510, in profile
    return render(request, 'accounts/profile.html')
  File "C:\Users\parit\AppData\Roaming\Python\Python313\site-packages\django\shortcuts.py", line 25, in render
    content = loader.render_to_string(template_name, context, request, using=using)
  File "C:\Users\parit\AppData\Roaming\Python\Python313\site-packages\django\template\loader.py", line 62, in render_to_string
    return template.render(context, request)
           ~~~~~~~~~~~~~~~^^^^^^^^^^^^^^^^^^
  File "C:\Users\parit\AppData\Roaming\Python\Python313\site-packages\django\template\backends\django.py", line 107, in render
    return self.template.render(context)
           ~~~~~~~~~~~~~~~~~~~~^^^^^^^^^
  File "C:\Users\parit\AppData\Roaming\Python\Python313\site-packages\django\template\base.py", line 171, in render
    return self._render(context)
           ~~~~~~~~~~~~^^^^^^^^^
  File "C:\Users\parit\AppData\Roaming\Python\Python313\site-packages\django\template\base.py", line 163, in _render
    return self.nodelist.render(context)
           ~~~~~~~~~~~~~~~~~~~~^^^^^^^^^
  File "C:\Users\parit\AppData\Roaming\Python\Python313\site-packages\django\template\base.py", line 1008, in render
    return SafeString("".join([node.render_annotated(context) for node in self]))
                               ~~~~~~~~~~~~~~~~~~~~~^^^^^^^^^
  File "C:\Users\parit\AppData\Roaming\Python\Python313\site-packages\django\template\base.py", line 969, in render_annotated
    return self.render(context)
           ~~~~~~~~~~~^^^^^^^^^
  File "C:\Users\parit\AppData\Roaming\Python\Python313\site-packages\django\template\defaulttags.py", line 480, in render
    url = reverse(view_name, args=args, kwargs=kwargs, current_app=current_app)
  File "C:\Users\parit\AppData\Roaming\Python\Python313\site-packages\django\urls\base.py", line 88, in reverse
    return resolver._reverse_with_prefix(view, prefix, *args, **kwargs)
           ~~~~~~~~~~~~~~~~~~~~~~~~~~~~~^^^^^^^^^^^^^^^^^^^^^^^^^^^^^^^
  File "C:\Users\parit\AppData\Roaming\Python\Python313\site-packages\django\urls\resolvers.py", line 831, in _reverse_with_prefix
    raise NoReverseMatch(msg)
django.urls.exceptions.NoReverseMatch: Reverse for 'budget_alerts' not found. 'budget_alerts' is not a valid view function or pattern name.
"GET /profile/?first_login=true HTTP/1.1" 500 122913
Internal Server Error: /budget_alerts/
Traceback (most recent call last):
  File "C:\Users\parit\AppData\Roaming\Python\Python313\site-packages\django\core\handlers\exception.py", line 55, in inner
    response = get_response(request)
  File "C:\Users\parit\AppData\Roaming\Python\Python313\site-packages\django\core\handlers\base.py", line 197, in _get_response
    response = wrapped_callback(request, *callback_args, **callback_kwargs)
  File "C:\Users\parit\Downloads\Infosys_Project_Intelligent_Financial_Tracker (3) (1)\project_team4\Infosys_Project_Intelligent_Financial_Tracker\personal_financial_tracker\accounts\views.py", line 777, in budget_alerts
    return render(request, 'budget_alerts.html')
  File "C:\Users\parit\AppData\Roaming\Python\Python313\site-packages\django\shortcuts.py", line 25, in render
    content = loader.render_to_string(template_name, context, request, using=using)
  File "C:\Users\parit\AppData\Roaming\Python\Python313\site-packages\django\template\loader.py", line 61, in render_to_string
    template = get_template(template_name, using=using)
  File "C:\Users\parit\AppData\Roaming\Python\Python313\site-packages\django\template\loader.py", line 19, in get_template
    raise TemplateDoesNotExist(template_name, chain=chain)
django.template.exceptions.TemplateDoesNotExist: budget_alerts.html
"GET /budget_alerts/ HTTP/1.1" 500 80634
Internal Server Error: /set-budget/
Traceback (most recent call last):
  File "C:\Users\parit\AppData\Roaming\Python\Python313\site-packages\django\core\handlers\exception.py", line 55, in inner
    response = get_response(request)
  File "C:\Users\parit\AppData\Roaming\Python\Python313\site-packages\django\core\handlers\base.py", line 204, in _get_response
    self.check_response(response, callback)
    ~~~~~~~~~~~~~~~~~~~^^^^^^^^^^^^^^^^^^^^
  File "C:\Users\parit\AppData\Roaming\Python\Python313\site-packages\django\core\handlers\base.py", line 332, in check_response
    raise ValueError(
    ...<2 lines>...
    )
ValueError: The view accounts.views.set_budget didn't return an HttpResponse object. It returned None instead.
"GET /set-budget/ HTTP/1.1" 500 66430
Internal Server Error: /financial_dashboard/
Traceback (most recent call last):
  File "C:\Users\parit\AppData\Roaming\Python\Python313\site-packages\django\core\handlers\exception.py", line 55, in inner
    response = get_response(request)
  File "C:\Users\parit\AppData\Roaming\Python\Python313\site-packages\django\core\handlers\base.py", line 197, in _get_response
    response = wrapped_callback(request, *callback_args, **callback_kwargs)
  File "C:\Users\parit\AppData\Roaming\Python\Python313\site-packages\django\contrib\auth\decorators.py", line 60, in _view_wrapper
    return view_func(request, *args, **kwargs)
  File "C:\Users\parit\Downloads\Infosys_Project_Intelligent_Financial_Tracker (3) (1)\project_team4\Infosys_Project_Intelligent_Financial_Tracker\personal_financial_tracker\accounts\views.py", line 753, in financial_dashboard
    total_expenses = calculate_total_expenses()  # Your logic to calculate total expenses
                     ^^^^^^^^^^^^^^^^^^^^^^^^
NameError: name 'calculate_total_expenses' is not defined
"GET /financial_dashboard/ HTTP/1.1" 500 71451
